Traceback (most recent call last):
  File "/opt/conda/envs/flow-latest/lib/python3.5/site-packages/ray/tune/trial_runner.py", line 443, in _process_trial
    result = self.trial_executor.fetch_result(trial)
  File "/opt/conda/envs/flow-latest/lib/python3.5/site-packages/ray/tune/ray_trial_executor.py", line 315, in fetch_result
    result = ray.get(trial_future[0])
  File "/opt/conda/envs/flow-latest/lib/python3.5/site-packages/ray/worker.py", line 2193, in get
    raise value
ray.exceptions.RayTaskError: [36mray_PPOTrainer:train()[39m (pid=45043, host=flow-main)
  File "/opt/conda/envs/flow-latest/lib/python3.5/site-packages/ray/rllib/agents/trainer.py", line 333, in train
    raise e
  File "/opt/conda/envs/flow-latest/lib/python3.5/site-packages/ray/rllib/agents/trainer.py", line 322, in train
    result = Trainable.train(self)
  File "/opt/conda/envs/flow-latest/lib/python3.5/site-packages/ray/tune/trainable.py", line 151, in train
    result = self._train()
  File "/opt/conda/envs/flow-latest/lib/python3.5/site-packages/ray/rllib/agents/ppo/ppo.py", line 110, in _train
    fetches = self.optimizer.step()
  File "/opt/conda/envs/flow-latest/lib/python3.5/site-packages/ray/rllib/optimizers/multi_gpu_optimizer.py", line 129, in step
    self.num_envs_per_worker, self.train_batch_size)
  File "/opt/conda/envs/flow-latest/lib/python3.5/site-packages/ray/rllib/optimizers/rollout.py", line 28, in collect_samples
    next_sample = ray.get(fut_sample)
ray.exceptions.RayTaskError: [36mray_PolicyEvaluator:sample()[39m (pid=45082, host=flow-main)
  File "/opt/conda/envs/flow-latest/lib/python3.5/site-packages/ray/rllib/evaluation/policy_evaluator.py", line 439, in sample
    batches = [self.input_reader.next()]
  File "/opt/conda/envs/flow-latest/lib/python3.5/site-packages/ray/rllib/evaluation/sampler.py", line 60, in next
    batches = [self.get_data()]
  File "/opt/conda/envs/flow-latest/lib/python3.5/site-packages/ray/rllib/evaluation/sampler.py", line 101, in get_data
    item = next(self.rollout_provider)
  File "/opt/conda/envs/flow-latest/lib/python3.5/site-packages/ray/rllib/evaluation/sampler.py", line 317, in _env_runner
    soft_horizon)
  File "/opt/conda/envs/flow-latest/lib/python3.5/site-packages/ray/rllib/evaluation/sampler.py", line 405, in _process_observations
    policy_id).transform(raw_obs)
  File "/opt/conda/envs/flow-latest/lib/python3.5/site-packages/ray/rllib/models/preprocessors.py", line 162, in transform
    self.check_shape(observation)
  File "/opt/conda/envs/flow-latest/lib/python3.5/site-packages/ray/rllib/models/preprocessors.py", line 61, in check_shape
    self._obs_space, observation)
ValueError: ('Observation outside expected value range', Box(12,), array([ 4.9021786e-01,  1.7157702e-01,  9.9845961e-02,  2.6597049e-02,
        2.0489775e-02,  4.5415148e-01, -3.3366665e+01,  3.4366665e+01,
        1.0000000e+00, -3.3366665e+01,  1.0000000e+00,  0.0000000e+00],
      dtype=float32))


