Traceback (most recent call last):
  File "/opt/conda/envs/flow/lib/python3.5/site-packages/ray/tune/trial_runner.py", line 261, in _process_events
    result = self.trial_executor.fetch_result(trial)
  File "/opt/conda/envs/flow/lib/python3.5/site-packages/ray/tune/ray_trial_executor.py", line 211, in fetch_result
    result = ray.get(trial_future[0])
  File "/opt/conda/envs/flow/lib/python3.5/site-packages/ray/worker.py", line 2386, in get
    raise value
ray.worker.RayTaskError: [36mray_PPOAgent:train()[39m (pid=39409, host=flow-main)
  File "/opt/conda/envs/flow/lib/python3.5/site-packages/ray/rllib/agents/agent.py", line 279, in train
    result = Trainable.train(self)
  File "/opt/conda/envs/flow/lib/python3.5/site-packages/ray/tune/trainable.py", line 146, in train
    result = self._train()
  File "/opt/conda/envs/flow/lib/python3.5/site-packages/ray/rllib/agents/ppo/ppo.py", line 101, in _train
    fetches = self.optimizer.step()
  File "/opt/conda/envs/flow/lib/python3.5/site-packages/ray/rllib/optimizers/multi_gpu_optimizer.py", line 125, in step
    self.num_envs_per_worker, self.train_batch_size)
  File "/opt/conda/envs/flow/lib/python3.5/site-packages/ray/rllib/optimizers/rollout.py", line 29, in collect_samples
    assert next_sample.count >= sample_batch_size * num_envs_per_worker
AssertionError

